[2022-04-18 02:24:51,137] 127.0.0.1 requested http://127.0.0.1:5000/register
ERROR in app: Exception on /register [POST]
Traceback (most recent call last):
  File "C:\Users\HP\Desktop\Fiver\America_Client\Noor\Project-3\venv\lib\site-packages\sqlalchemy\engine\base.py", line 3280, in _wrap_pool_connect
    return fn()
  File "C:\Users\HP\Desktop\Fiver\America_Client\Noor\Project-3\venv\lib\site-packages\sqlalchemy\pool\base.py", line 310, in connect
    return _ConnectionFairy._checkout(self)
  File "C:\Users\HP\Desktop\Fiver\America_Client\Noor\Project-3\venv\lib\site-packages\sqlalchemy\pool\base.py", line 868, in _checkout
    fairy = _ConnectionRecord.checkout(pool)
  File "C:\Users\HP\Desktop\Fiver\America_Client\Noor\Project-3\venv\lib\site-packages\sqlalchemy\pool\base.py", line 476, in checkout
    rec = pool._do_get()
  File "C:\Users\HP\Desktop\Fiver\America_Client\Noor\Project-3\venv\lib\site-packages\sqlalchemy\pool\impl.py", line 256, in _do_get
    return self._create_connection()
  File "C:\Users\HP\Desktop\Fiver\America_Client\Noor\Project-3\venv\lib\site-packages\sqlalchemy\pool\base.py", line 256, in _create_connection
    return _ConnectionRecord(self)
  File "C:\Users\HP\Desktop\Fiver\America_Client\Noor\Project-3\venv\lib\site-packages\sqlalchemy\pool\base.py", line 371, in __init__
    self.__connect()
  File "C:\Users\HP\Desktop\Fiver\America_Client\Noor\Project-3\venv\lib\site-packages\sqlalchemy\pool\base.py", line 665, in __connect
    with util.safe_reraise():
  File "C:\Users\HP\Desktop\Fiver\America_Client\Noor\Project-3\venv\lib\site-packages\sqlalchemy\util\langhelpers.py", line 70, in __exit__
    compat.raise_(
  File "C:\Users\HP\Desktop\Fiver\America_Client\Noor\Project-3\venv\lib\site-packages\sqlalchemy\util\compat.py", line 207, in raise_
    raise exception
  File "C:\Users\HP\Desktop\Fiver\America_Client\Noor\Project-3\venv\lib\site-packages\sqlalchemy\pool\base.py", line 661, in __connect
    self.dbapi_connection = connection = pool._invoke_creator(self)
  File "C:\Users\HP\Desktop\Fiver\America_Client\Noor\Project-3\venv\lib\site-packages\sqlalchemy\engine\create.py", line 590, in connect
    return dialect.connect(*cargs, **cparams)
  File "C:\Users\HP\Desktop\Fiver\America_Client\Noor\Project-3\venv\lib\site-packages\sqlalchemy\engine\default.py", line 597, in connect
    return self.dbapi.connect(*cargs, **cparams)
sqlite3.OperationalError: unable to open database file

The above exception was the direct cause of the following exception:

Traceback (most recent call last):
  File "C:\Users\HP\Desktop\Fiver\America_Client\Noor\Project-3\venv\lib\site-packages\flask\app.py", line 2077, in wsgi_app
    response = self.full_dispatch_request()
  File "C:\Users\HP\Desktop\Fiver\America_Client\Noor\Project-3\venv\lib\site-packages\flask\app.py", line 1525, in full_dispatch_request
    rv = self.handle_user_exception(e)
  File "C:\Users\HP\Desktop\Fiver\America_Client\Noor\Project-3\venv\lib\site-packages\flask\app.py", line 1523, in full_dispatch_request
    rv = self.dispatch_request()
  File "C:\Users\HP\Desktop\Fiver\America_Client\Noor\Project-3\venv\lib\site-packages\flask\app.py", line 1509, in dispatch_request
    return self.ensure_sync(self.view_functions[rule.endpoint])(**req.view_args)
  File "C:\Users\HP\Desktop\Fiver\America_Client\Noor\Project-3\app\auth\__init__.py", line 39, in register
    user = User.query.filter_by(email=form.email.data).first()
  File "C:\Users\HP\Desktop\Fiver\America_Client\Noor\Project-3\venv\lib\site-packages\sqlalchemy\orm\query.py", line 2819, in first
    return self.limit(1)._iter().first()
  File "C:\Users\HP\Desktop\Fiver\America_Client\Noor\Project-3\venv\lib\site-packages\sqlalchemy\orm\query.py", line 2903, in _iter
    result = self.session.execute(
  File "C:\Users\HP\Desktop\Fiver\America_Client\Noor\Project-3\venv\lib\site-packages\sqlalchemy\orm\session.py", line 1691, in execute
    conn = self._connection_for_bind(bind)
  File "C:\Users\HP\Desktop\Fiver\America_Client\Noor\Project-3\venv\lib\site-packages\sqlalchemy\orm\session.py", line 1532, in _connection_for_bind
    return self._transaction._connection_for_bind(
  File "C:\Users\HP\Desktop\Fiver\America_Client\Noor\Project-3\venv\lib\site-packages\sqlalchemy\orm\session.py", line 747, in _connection_for_bind
    conn = bind.connect()
  File "C:\Users\HP\Desktop\Fiver\America_Client\Noor\Project-3\venv\lib\site-packages\sqlalchemy\engine\base.py", line 3234, in connect
    return self._connection_cls(self, close_with_result=close_with_result)
  File "C:\Users\HP\Desktop\Fiver\America_Client\Noor\Project-3\venv\lib\site-packages\sqlalchemy\engine\base.py", line 96, in __init__
    else engine.raw_connection()
  File "C:\Users\HP\Desktop\Fiver\America_Client\Noor\Project-3\venv\lib\site-packages\sqlalchemy\engine\base.py", line 3313, in raw_connection
    return self._wrap_pool_connect(self.pool.connect, _connection)
  File "C:\Users\HP\Desktop\Fiver\America_Client\Noor\Project-3\venv\lib\site-packages\sqlalchemy\engine\base.py", line 3283, in _wrap_pool_connect
    Connection._handle_dbapi_exception_noconnection(
  File "C:\Users\HP\Desktop\Fiver\America_Client\Noor\Project-3\venv\lib\site-packages\sqlalchemy\engine\base.py", line 2117, in _handle_dbapi_exception_noconnection
    util.raise_(
  File "C:\Users\HP\Desktop\Fiver\America_Client\Noor\Project-3\venv\lib\site-packages\sqlalchemy\util\compat.py", line 207, in raise_
    raise exception
  File "C:\Users\HP\Desktop\Fiver\America_Client\Noor\Project-3\venv\lib\site-packages\sqlalchemy\engine\base.py", line 3280, in _wrap_pool_connect
    return fn()
  File "C:\Users\HP\Desktop\Fiver\America_Client\Noor\Project-3\venv\lib\site-packages\sqlalchemy\pool\base.py", line 310, in connect
    return _ConnectionFairy._checkout(self)
  File "C:\Users\HP\Desktop\Fiver\America_Client\Noor\Project-3\venv\lib\site-packages\sqlalchemy\pool\base.py", line 868, in _checkout
    fairy = _ConnectionRecord.checkout(pool)
  File "C:\Users\HP\Desktop\Fiver\America_Client\Noor\Project-3\venv\lib\site-packages\sqlalchemy\pool\base.py", line 476, in checkout
    rec = pool._do_get()
  File "C:\Users\HP\Desktop\Fiver\America_Client\Noor\Project-3\venv\lib\site-packages\sqlalchemy\pool\impl.py", line 256, in _do_get
    return self._create_connection()
  File "C:\Users\HP\Desktop\Fiver\America_Client\Noor\Project-3\venv\lib\site-packages\sqlalchemy\pool\base.py", line 256, in _create_connection
    return _ConnectionRecord(self)
  File "C:\Users\HP\Desktop\Fiver\America_Client\Noor\Project-3\venv\lib\site-packages\sqlalchemy\pool\base.py", line 371, in __init__
    self.__connect()
  File "C:\Users\HP\Desktop\Fiver\America_Client\Noor\Project-3\venv\lib\site-packages\sqlalchemy\pool\base.py", line 665, in __connect
    with util.safe_reraise():
  File "C:\Users\HP\Desktop\Fiver\America_Client\Noor\Project-3\venv\lib\site-packages\sqlalchemy\util\langhelpers.py", line 70, in __exit__
    compat.raise_(
  File "C:\Users\HP\Desktop\Fiver\America_Client\Noor\Project-3\venv\lib\site-packages\sqlalchemy\util\compat.py", line 207, in raise_
    raise exception
  File "C:\Users\HP\Desktop\Fiver\America_Client\Noor\Project-3\venv\lib\site-packages\sqlalchemy\pool\base.py", line 661, in __connect
    self.dbapi_connection = connection = pool._invoke_creator(self)
  File "C:\Users\HP\Desktop\Fiver\America_Client\Noor\Project-3\venv\lib\site-packages\sqlalchemy\engine\create.py", line 590, in connect
    return dialect.connect(*cargs, **cparams)
  File "C:\Users\HP\Desktop\Fiver\America_Client\Noor\Project-3\venv\lib\site-packages\sqlalchemy\engine\default.py", line 597, in connect
    return self.dbapi.connect(*cargs, **cparams)
sqlalchemy.exc.OperationalError: (sqlite3.OperationalError) unable to open database file
(Background on this error at: https://sqlalche.me/e/14/e3q8)
[2022-04-18 02:25:32,763] 127.0.0.1 requested http://127.0.0.1:5000/register
ERROR in app: Exception on /register [POST]
Traceback (most recent call last):
  File "C:\Users\HP\Desktop\Fiver\America_Client\Noor\Project-3\venv\lib\site-packages\sqlalchemy\engine\base.py", line 3280, in _wrap_pool_connect
    return fn()
  File "C:\Users\HP\Desktop\Fiver\America_Client\Noor\Project-3\venv\lib\site-packages\sqlalchemy\pool\base.py", line 310, in connect
    return _ConnectionFairy._checkout(self)
  File "C:\Users\HP\Desktop\Fiver\America_Client\Noor\Project-3\venv\lib\site-packages\sqlalchemy\pool\base.py", line 868, in _checkout
    fairy = _ConnectionRecord.checkout(pool)
  File "C:\Users\HP\Desktop\Fiver\America_Client\Noor\Project-3\venv\lib\site-packages\sqlalchemy\pool\base.py", line 476, in checkout
    rec = pool._do_get()
  File "C:\Users\HP\Desktop\Fiver\America_Client\Noor\Project-3\venv\lib\site-packages\sqlalchemy\pool\impl.py", line 256, in _do_get
    return self._create_connection()
  File "C:\Users\HP\Desktop\Fiver\America_Client\Noor\Project-3\venv\lib\site-packages\sqlalchemy\pool\base.py", line 256, in _create_connection
    return _ConnectionRecord(self)
  File "C:\Users\HP\Desktop\Fiver\America_Client\Noor\Project-3\venv\lib\site-packages\sqlalchemy\pool\base.py", line 371, in __init__
    self.__connect()
  File "C:\Users\HP\Desktop\Fiver\America_Client\Noor\Project-3\venv\lib\site-packages\sqlalchemy\pool\base.py", line 665, in __connect
    with util.safe_reraise():
  File "C:\Users\HP\Desktop\Fiver\America_Client\Noor\Project-3\venv\lib\site-packages\sqlalchemy\util\langhelpers.py", line 70, in __exit__
    compat.raise_(
  File "C:\Users\HP\Desktop\Fiver\America_Client\Noor\Project-3\venv\lib\site-packages\sqlalchemy\util\compat.py", line 207, in raise_
    raise exception
  File "C:\Users\HP\Desktop\Fiver\America_Client\Noor\Project-3\venv\lib\site-packages\sqlalchemy\pool\base.py", line 661, in __connect
    self.dbapi_connection = connection = pool._invoke_creator(self)
  File "C:\Users\HP\Desktop\Fiver\America_Client\Noor\Project-3\venv\lib\site-packages\sqlalchemy\engine\create.py", line 590, in connect
    return dialect.connect(*cargs, **cparams)
  File "C:\Users\HP\Desktop\Fiver\America_Client\Noor\Project-3\venv\lib\site-packages\sqlalchemy\engine\default.py", line 597, in connect
    return self.dbapi.connect(*cargs, **cparams)
sqlite3.OperationalError: unable to open database file

The above exception was the direct cause of the following exception:

Traceback (most recent call last):
  File "C:\Users\HP\Desktop\Fiver\America_Client\Noor\Project-3\venv\lib\site-packages\flask\app.py", line 2077, in wsgi_app
    response = self.full_dispatch_request()
  File "C:\Users\HP\Desktop\Fiver\America_Client\Noor\Project-3\venv\lib\site-packages\flask\app.py", line 1525, in full_dispatch_request
    rv = self.handle_user_exception(e)
  File "C:\Users\HP\Desktop\Fiver\America_Client\Noor\Project-3\venv\lib\site-packages\flask\app.py", line 1523, in full_dispatch_request
    rv = self.dispatch_request()
  File "C:\Users\HP\Desktop\Fiver\America_Client\Noor\Project-3\venv\lib\site-packages\flask\app.py", line 1509, in dispatch_request
    return self.ensure_sync(self.view_functions[rule.endpoint])(**req.view_args)
  File "C:\Users\HP\Desktop\Fiver\America_Client\Noor\Project-3\app\auth\__init__.py", line 39, in register
    user = User.query.filter_by(email=form.email.data).first()
  File "C:\Users\HP\Desktop\Fiver\America_Client\Noor\Project-3\venv\lib\site-packages\sqlalchemy\orm\query.py", line 2819, in first
    return self.limit(1)._iter().first()
  File "C:\Users\HP\Desktop\Fiver\America_Client\Noor\Project-3\venv\lib\site-packages\sqlalchemy\orm\query.py", line 2903, in _iter
    result = self.session.execute(
  File "C:\Users\HP\Desktop\Fiver\America_Client\Noor\Project-3\venv\lib\site-packages\sqlalchemy\orm\session.py", line 1691, in execute
    conn = self._connection_for_bind(bind)
  File "C:\Users\HP\Desktop\Fiver\America_Client\Noor\Project-3\venv\lib\site-packages\sqlalchemy\orm\session.py", line 1532, in _connection_for_bind
    return self._transaction._connection_for_bind(
  File "C:\Users\HP\Desktop\Fiver\America_Client\Noor\Project-3\venv\lib\site-packages\sqlalchemy\orm\session.py", line 747, in _connection_for_bind
    conn = bind.connect()
  File "C:\Users\HP\Desktop\Fiver\America_Client\Noor\Project-3\venv\lib\site-packages\sqlalchemy\engine\base.py", line 3234, in connect
    return self._connection_cls(self, close_with_result=close_with_result)
  File "C:\Users\HP\Desktop\Fiver\America_Client\Noor\Project-3\venv\lib\site-packages\sqlalchemy\engine\base.py", line 96, in __init__
    else engine.raw_connection()
  File "C:\Users\HP\Desktop\Fiver\America_Client\Noor\Project-3\venv\lib\site-packages\sqlalchemy\engine\base.py", line 3313, in raw_connection
    return self._wrap_pool_connect(self.pool.connect, _connection)
  File "C:\Users\HP\Desktop\Fiver\America_Client\Noor\Project-3\venv\lib\site-packages\sqlalchemy\engine\base.py", line 3283, in _wrap_pool_connect
    Connection._handle_dbapi_exception_noconnection(
  File "C:\Users\HP\Desktop\Fiver\America_Client\Noor\Project-3\venv\lib\site-packages\sqlalchemy\engine\base.py", line 2117, in _handle_dbapi_exception_noconnection
    util.raise_(
  File "C:\Users\HP\Desktop\Fiver\America_Client\Noor\Project-3\venv\lib\site-packages\sqlalchemy\util\compat.py", line 207, in raise_
    raise exception
  File "C:\Users\HP\Desktop\Fiver\America_Client\Noor\Project-3\venv\lib\site-packages\sqlalchemy\engine\base.py", line 3280, in _wrap_pool_connect
    return fn()
  File "C:\Users\HP\Desktop\Fiver\America_Client\Noor\Project-3\venv\lib\site-packages\sqlalchemy\pool\base.py", line 310, in connect
    return _ConnectionFairy._checkout(self)
  File "C:\Users\HP\Desktop\Fiver\America_Client\Noor\Project-3\venv\lib\site-packages\sqlalchemy\pool\base.py", line 868, in _checkout
    fairy = _ConnectionRecord.checkout(pool)
  File "C:\Users\HP\Desktop\Fiver\America_Client\Noor\Project-3\venv\lib\site-packages\sqlalchemy\pool\base.py", line 476, in checkout
    rec = pool._do_get()
  File "C:\Users\HP\Desktop\Fiver\America_Client\Noor\Project-3\venv\lib\site-packages\sqlalchemy\pool\impl.py", line 256, in _do_get
    return self._create_connection()
  File "C:\Users\HP\Desktop\Fiver\America_Client\Noor\Project-3\venv\lib\site-packages\sqlalchemy\pool\base.py", line 256, in _create_connection
    return _ConnectionRecord(self)
  File "C:\Users\HP\Desktop\Fiver\America_Client\Noor\Project-3\venv\lib\site-packages\sqlalchemy\pool\base.py", line 371, in __init__
    self.__connect()
  File "C:\Users\HP\Desktop\Fiver\America_Client\Noor\Project-3\venv\lib\site-packages\sqlalchemy\pool\base.py", line 665, in __connect
    with util.safe_reraise():
  File "C:\Users\HP\Desktop\Fiver\America_Client\Noor\Project-3\venv\lib\site-packages\sqlalchemy\util\langhelpers.py", line 70, in __exit__
    compat.raise_(
  File "C:\Users\HP\Desktop\Fiver\America_Client\Noor\Project-3\venv\lib\site-packages\sqlalchemy\util\compat.py", line 207, in raise_
    raise exception
  File "C:\Users\HP\Desktop\Fiver\America_Client\Noor\Project-3\venv\lib\site-packages\sqlalchemy\pool\base.py", line 661, in __connect
    self.dbapi_connection = connection = pool._invoke_creator(self)
  File "C:\Users\HP\Desktop\Fiver\America_Client\Noor\Project-3\venv\lib\site-packages\sqlalchemy\engine\create.py", line 590, in connect
    return dialect.connect(*cargs, **cparams)
  File "C:\Users\HP\Desktop\Fiver\America_Client\Noor\Project-3\venv\lib\site-packages\sqlalchemy\engine\default.py", line 597, in connect
    return self.dbapi.connect(*cargs, **cparams)
sqlalchemy.exc.OperationalError: (sqlite3.OperationalError) unable to open database file
(Background on this error at: https://sqlalche.me/e/14/e3q8)
[2022-04-18 02:28:37,511] 127.0.0.1 requested http://127.0.0.1:5000/register
ERROR in app: Exception on /register [POST]
Traceback (most recent call last):
  File "C:\Users\HP\Desktop\Fiver\America_Client\Noor\Project-3\venv\lib\site-packages\sqlalchemy\engine\base.py", line 3280, in _wrap_pool_connect
    return fn()
  File "C:\Users\HP\Desktop\Fiver\America_Client\Noor\Project-3\venv\lib\site-packages\sqlalchemy\pool\base.py", line 310, in connect
    return _ConnectionFairy._checkout(self)
  File "C:\Users\HP\Desktop\Fiver\America_Client\Noor\Project-3\venv\lib\site-packages\sqlalchemy\pool\base.py", line 868, in _checkout
    fairy = _ConnectionRecord.checkout(pool)
  File "C:\Users\HP\Desktop\Fiver\America_Client\Noor\Project-3\venv\lib\site-packages\sqlalchemy\pool\base.py", line 476, in checkout
    rec = pool._do_get()
  File "C:\Users\HP\Desktop\Fiver\America_Client\Noor\Project-3\venv\lib\site-packages\sqlalchemy\pool\impl.py", line 256, in _do_get
    return self._create_connection()
  File "C:\Users\HP\Desktop\Fiver\America_Client\Noor\Project-3\venv\lib\site-packages\sqlalchemy\pool\base.py", line 256, in _create_connection
    return _ConnectionRecord(self)
  File "C:\Users\HP\Desktop\Fiver\America_Client\Noor\Project-3\venv\lib\site-packages\sqlalchemy\pool\base.py", line 371, in __init__
    self.__connect()
  File "C:\Users\HP\Desktop\Fiver\America_Client\Noor\Project-3\venv\lib\site-packages\sqlalchemy\pool\base.py", line 665, in __connect
    with util.safe_reraise():
  File "C:\Users\HP\Desktop\Fiver\America_Client\Noor\Project-3\venv\lib\site-packages\sqlalchemy\util\langhelpers.py", line 70, in __exit__
    compat.raise_(
  File "C:\Users\HP\Desktop\Fiver\America_Client\Noor\Project-3\venv\lib\site-packages\sqlalchemy\util\compat.py", line 207, in raise_
    raise exception
  File "C:\Users\HP\Desktop\Fiver\America_Client\Noor\Project-3\venv\lib\site-packages\sqlalchemy\pool\base.py", line 661, in __connect
    self.dbapi_connection = connection = pool._invoke_creator(self)
  File "C:\Users\HP\Desktop\Fiver\America_Client\Noor\Project-3\venv\lib\site-packages\sqlalchemy\engine\create.py", line 590, in connect
    return dialect.connect(*cargs, **cparams)
  File "C:\Users\HP\Desktop\Fiver\America_Client\Noor\Project-3\venv\lib\site-packages\sqlalchemy\engine\default.py", line 597, in connect
    return self.dbapi.connect(*cargs, **cparams)
sqlite3.OperationalError: unable to open database file

The above exception was the direct cause of the following exception:

Traceback (most recent call last):
  File "C:\Users\HP\Desktop\Fiver\America_Client\Noor\Project-3\venv\lib\site-packages\flask\app.py", line 2077, in wsgi_app
    response = self.full_dispatch_request()
  File "C:\Users\HP\Desktop\Fiver\America_Client\Noor\Project-3\venv\lib\site-packages\flask\app.py", line 1525, in full_dispatch_request
    rv = self.handle_user_exception(e)
  File "C:\Users\HP\Desktop\Fiver\America_Client\Noor\Project-3\venv\lib\site-packages\flask\app.py", line 1523, in full_dispatch_request
    rv = self.dispatch_request()
  File "C:\Users\HP\Desktop\Fiver\America_Client\Noor\Project-3\venv\lib\site-packages\flask\app.py", line 1509, in dispatch_request
    return self.ensure_sync(self.view_functions[rule.endpoint])(**req.view_args)
  File "C:\Users\HP\Desktop\Fiver\America_Client\Noor\Project-3\app\auth\__init__.py", line 39, in register
    user = User.query.filter_by(email=form.email.data).first()
  File "C:\Users\HP\Desktop\Fiver\America_Client\Noor\Project-3\venv\lib\site-packages\sqlalchemy\orm\query.py", line 2819, in first
    return self.limit(1)._iter().first()
  File "C:\Users\HP\Desktop\Fiver\America_Client\Noor\Project-3\venv\lib\site-packages\sqlalchemy\orm\query.py", line 2903, in _iter
    result = self.session.execute(
  File "C:\Users\HP\Desktop\Fiver\America_Client\Noor\Project-3\venv\lib\site-packages\sqlalchemy\orm\session.py", line 1691, in execute
    conn = self._connection_for_bind(bind)
  File "C:\Users\HP\Desktop\Fiver\America_Client\Noor\Project-3\venv\lib\site-packages\sqlalchemy\orm\session.py", line 1532, in _connection_for_bind
    return self._transaction._connection_for_bind(
  File "C:\Users\HP\Desktop\Fiver\America_Client\Noor\Project-3\venv\lib\site-packages\sqlalchemy\orm\session.py", line 747, in _connection_for_bind
    conn = bind.connect()
  File "C:\Users\HP\Desktop\Fiver\America_Client\Noor\Project-3\venv\lib\site-packages\sqlalchemy\engine\base.py", line 3234, in connect
    return self._connection_cls(self, close_with_result=close_with_result)
  File "C:\Users\HP\Desktop\Fiver\America_Client\Noor\Project-3\venv\lib\site-packages\sqlalchemy\engine\base.py", line 96, in __init__
    else engine.raw_connection()
  File "C:\Users\HP\Desktop\Fiver\America_Client\Noor\Project-3\venv\lib\site-packages\sqlalchemy\engine\base.py", line 3313, in raw_connection
    return self._wrap_pool_connect(self.pool.connect, _connection)
  File "C:\Users\HP\Desktop\Fiver\America_Client\Noor\Project-3\venv\lib\site-packages\sqlalchemy\engine\base.py", line 3283, in _wrap_pool_connect
    Connection._handle_dbapi_exception_noconnection(
  File "C:\Users\HP\Desktop\Fiver\America_Client\Noor\Project-3\venv\lib\site-packages\sqlalchemy\engine\base.py", line 2117, in _handle_dbapi_exception_noconnection
    util.raise_(
  File "C:\Users\HP\Desktop\Fiver\America_Client\Noor\Project-3\venv\lib\site-packages\sqlalchemy\util\compat.py", line 207, in raise_
    raise exception
  File "C:\Users\HP\Desktop\Fiver\America_Client\Noor\Project-3\venv\lib\site-packages\sqlalchemy\engine\base.py", line 3280, in _wrap_pool_connect
    return fn()
  File "C:\Users\HP\Desktop\Fiver\America_Client\Noor\Project-3\venv\lib\site-packages\sqlalchemy\pool\base.py", line 310, in connect
    return _ConnectionFairy._checkout(self)
  File "C:\Users\HP\Desktop\Fiver\America_Client\Noor\Project-3\venv\lib\site-packages\sqlalchemy\pool\base.py", line 868, in _checkout
    fairy = _ConnectionRecord.checkout(pool)
  File "C:\Users\HP\Desktop\Fiver\America_Client\Noor\Project-3\venv\lib\site-packages\sqlalchemy\pool\base.py", line 476, in checkout
    rec = pool._do_get()
  File "C:\Users\HP\Desktop\Fiver\America_Client\Noor\Project-3\venv\lib\site-packages\sqlalchemy\pool\impl.py", line 256, in _do_get
    return self._create_connection()
  File "C:\Users\HP\Desktop\Fiver\America_Client\Noor\Project-3\venv\lib\site-packages\sqlalchemy\pool\base.py", line 256, in _create_connection
    return _ConnectionRecord(self)
  File "C:\Users\HP\Desktop\Fiver\America_Client\Noor\Project-3\venv\lib\site-packages\sqlalchemy\pool\base.py", line 371, in __init__
    self.__connect()
  File "C:\Users\HP\Desktop\Fiver\America_Client\Noor\Project-3\venv\lib\site-packages\sqlalchemy\pool\base.py", line 665, in __connect
    with util.safe_reraise():
  File "C:\Users\HP\Desktop\Fiver\America_Client\Noor\Project-3\venv\lib\site-packages\sqlalchemy\util\langhelpers.py", line 70, in __exit__
    compat.raise_(
  File "C:\Users\HP\Desktop\Fiver\America_Client\Noor\Project-3\venv\lib\site-packages\sqlalchemy\util\compat.py", line 207, in raise_
    raise exception
  File "C:\Users\HP\Desktop\Fiver\America_Client\Noor\Project-3\venv\lib\site-packages\sqlalchemy\pool\base.py", line 661, in __connect
    self.dbapi_connection = connection = pool._invoke_creator(self)
  File "C:\Users\HP\Desktop\Fiver\America_Client\Noor\Project-3\venv\lib\site-packages\sqlalchemy\engine\create.py", line 590, in connect
    return dialect.connect(*cargs, **cparams)
  File "C:\Users\HP\Desktop\Fiver\America_Client\Noor\Project-3\venv\lib\site-packages\sqlalchemy\engine\default.py", line 597, in connect
    return self.dbapi.connect(*cargs, **cparams)
sqlalchemy.exc.OperationalError: (sqlite3.OperationalError) unable to open database file
(Background on this error at: https://sqlalche.me/e/14/e3q8)
[2022-04-19 22:21:58,589] 127.0.0.1 requested http://127.0.0.1:5000/
INFO in __init__: this is the plain message
[2022-04-19 22:22:01,520] 127.0.0.1 requested http://127.0.0.1:5000/register
INFO in __init__: this is the plain message
[2022-04-19 22:26:09,586] 127.0.0.1 requested http://127.0.0.1:5000/register
INFO in __init__: this is the plain message
[2022-04-19 23:33:58,676] 127.0.0.1 requested http://127.0.0.1:5000/
INFO in __init__: this is the plain message
[2022-04-19 23:34:00,409] 127.0.0.1 requested http://127.0.0.1:5000/register
INFO in __init__: this is the plain message
[2022-04-19 23:34:09,712] 127.0.0.1 requested http://127.0.0.1:5000/register
INFO in __init__: this is the plain message
[2022-04-19 23:48:39,956] 127.0.0.1 requested http://127.0.0.1:5000/about
INFO in __init__: this is the plain message
[2022-04-19 23:48:40,633] 127.0.0.1 requested http://127.0.0.1:5000/welcome
INFO in __init__: this is the plain message
[2022-04-19 23:49:20,745] 127.0.0.1 requested http://127.0.0.1:5000/about
INFO in __init__: this is the plain message
[2022-04-20 02:12:47,727] 127.0.0.1 requested http://127.0.0.1:5000/
INFO in __init__: this is the plain message
[2022-04-20 03:29:10,839] 127.0.0.1 requested http://127.0.0.1:5000/
INFO in __init__: this is the plain message
[2022-04-20 03:43:38,199] 127.0.0.1 requested http://127.0.0.1:5000/
INFO in __init__: this is the plain message
